<mujoco model="GEN3_URDF">
	<compiler angle="radian"/>
	<size njmax="500" nconmax="100"/>

	<asset>
		<!-- Gen3 Arm Meshes -->
		<mesh name="base_link" file="gen3/Base_Link.stl"/>
		<mesh name="Shoulder_Link" file="gen3/Shoulder_Link.stl"/>
		<mesh name="HalfArm1_Link" file="gen3/HalfArm1_Link.stl"/>
		<mesh name="HalfArm2_Link" file="gen3/HalfArm2_Link.stl"/>
		<mesh name="ForeArm_Link" file="gen3/ForeArm_Link.stl"/>
		<mesh name="SphericalWrist1_Link" file="gen3/SphericalWrist1_Link.stl"/>
		<mesh name="SphericalWrist2_Link" file="gen3/SphericalWrist2_Link.stl"/>
		<mesh name="Bracelet_Link" file="gen3/Bracelet_Link.stl"/>
		<!-- Robotiq Hand Meshes -->
		<mesh name="kinova_robotiq_coupler" file="robotiq/kinova_robotiq_coupler.stl"/>
		<mesh name="robotiq_85_base_link" file="robotiq/robotiq_85_base_link.stl"/>
		<mesh name="robotiq_85_finger_link" file="robotiq/robotiq_85_finger_link.stl"/>
		<mesh name="robotiq_85_finger_tip_link" file="robotiq/robotiq_85_finger_tip_link.stl"/>
		<mesh name="robotiq_85_inner_knuckle_link" file="robotiq/robotiq_85_inner_knuckle_link.stl"/>
		<mesh name="robotiq_85_knuckle_link" file="robotiq/robotiq_85_knuckle_link.stl"/>
		<!-- Materials -->
		<material name="RobMat" specular="0.9" shininess="0.5" reflectance="0" rgba="0.7 0.7 0.7 1" emission="0.1" />
		<material name="GriMat" specular="0.9" shininess="0.5" reflectance="0" rgba="0.1 0.1 0.1 1" emission="0.1" />
		<material name="BasketMat" specular="0" shininess="0" reflectance="0" rgba="0.26 0.16 0.16796875 1" emission="0" />
		<material name="Light" specular="0" shininess="0.6" reflectance="0.9" rgba="0.5 0.5 1 1" emission="0.7" />
	</asset>

	<worldbody>
        <light directional="true" pos="-0.5 0.5 3" dir="0 0 -1" />
        <light directional="false" pos="-0.5 0.5 1.5" dir="0 -1 0" />
<!--         <geom name="workbench_down" pos="-0.6 0.6 -0.25" size="0.6 0.6 0.25" type="box" rgba="0 0 0 1" material="BasketMat" /> -->
		<!-- Set up floor and walls -->
 		<geom name="floor" pos="0 0 -0.66" size="10 10 1" type="plane" rgba="1 0.83 0.61 1" material="BasketMat" />
        <geom name="wall_1" pos="0 -1.4 1" size="2.5 2.5 1" type="plane" quat="0.707107 -0.707107 0 0" rgba="0.95 0.95 0.95 1" material="BasketMat" />
        <geom name="wall_2" pos="-2.185 0 1" size="2.5 2.5 1" type="plane" quat="0.707107 0 0.707107 0" rgba="0.95 0.95 0.95 1" material="BasketMat" />
        <!-- World Base Link -->
		<geom type="mesh" rgba="0.79216 0.81961 0.93333 1" mesh="base_link"/>
		<!-- Kinova Gen3 Arm Links -->
		<body name="Shoulder_Link" pos="6.1995e-05 0 0.15643" quat="-3.67321e-06 -1 0 0">
			<inertial pos="-2.3e-05 -0.010364 -0.07336" quat="0.707051 0.0451246 -0.0453544 0.704263" mass="1.37735" diaginertia="0.00488868 0.00457 0.00135132"/>
			<joint name="Actuator1" pos="0 0 0" axis="0 0 1"/>
			<geom type="mesh" rgba="0.75294 0.75294 0.75294 1" mesh="Shoulder_Link"/>

			<body name="HalfArm1_Link" pos="0 0.005375 -0.12838" quat="0.707105 0.707108 0 0">
				<inertial pos="-4.4e-05 -0.09958 -0.013278" quat="0.482348 0.516286 -0.516862 0.483366" mass="1.16367" diaginertia="0.0113017 0.011088 0.00102532"/>
				<joint name="Actuator2" pos="0 0 0" axis="0 0 1" limited="true" range="-2.2 2.2"/>
				<geom type="mesh" rgba="0.75294 0.75294 0.75294 1" mesh="HalfArm1_Link"/>

				<body name="HalfArm2_Link" pos="0 -0.21038 -0.006375" quat="0.707105 -0.707108 0 0">
					<inertial pos="-4.4e-05 -0.006641 -0.117892" quat="0.706144 0.0213722 -0.0209128 0.707437" mass="1.16366" diaginertia="0.0111633 0.010932 0.00100671"/>
					<joint name="Actuator3" pos="0 0 0" axis="0 0 1"/>
					<geom type="mesh" rgba="0.75294 0.75294 0.75294 1" mesh="HalfArm2_Link"/>

					<body name="ForeArm_Link" pos="0 0.006375 -0.21038" quat="0.707105 0.707108 0 0">
						<inertial pos="-1.8e-05 -0.075478 -0.015006" quat="0.483678 0.515961 -0.515859 0.483455" mass="0.930287" diaginertia="0.00834839 0.008147 0.000598606"/>
						<joint name="Actuator4" pos="0 0 0" axis="0 0 1" limited="true" range="-2.5656 2.5656"/>
						<geom type="mesh" rgba="0.75294 0.75294 0.75294 1" mesh="ForeArm_Link"/>

						<body name="SphericalWrist1_Link" pos="0 -0.20843 -0.006375" quat="0.707105 -0.707108 0 0">
							<inertial pos="1e-06 -0.009432 -0.063883" quat="0.703558 0.0707492 -0.0707492 0.703558" mass="0.678106" diaginertia="0.00165901 0.001596 0.000346988"/>
							<joint name="Actuator5" pos="0 0 0" axis="0 0 1"/>
							<geom type="mesh" rgba="0.75294 0.75294 0.75294 1" mesh="SphericalWrist1_Link"/>

							<body name="SphericalWrist2_Link" pos="0 0.00017505 -0.10593" quat="0.707105 0.707108 0 0">
								<inertial pos="1e-06 -0.045483 -0.00965" quat="0.44426 0.550121 -0.550121 0.44426" mass="0.678106" diaginertia="0.00170087 0.001641 0.00035013"/>
								<joint name="Actuator6" pos="0 0 0" axis="0 0 1" limited="true" range="-2.05 2.05"/>
								<geom type="mesh" rgba="0.75294 0.75294 0.75294 1" mesh="SphericalWrist2_Link"/>

								<body name="Bracelet_Link" pos="0 -0.10593 -0.00017505" quat="0.707105 -0.707108 0 0">
									<inertial pos="-0.000281 -0.011402 -0.03108" quat="0.592556 0.413116 -0.393675 0.568536" mass="0.500657" diaginertia="0.000650457 0.00056985 0.000310694"/>
									<joint name="Actuator7" pos="0 0 0" axis="0 0 1"/>
									<geom type="mesh" rgba="0.75294 0.75294 0.75294 1" mesh="Bracelet_Link"/>
									<!-- Robotiq Gripper Links -->
									<body name="EE_Link" pos="0 0 -0.0719" quat="0 0 0 0">
										<inertial pos="0 0 -0.0719" quat="0 0 0 0" mass="0" diaginertia="0 0 0" />
										<geom name="light_1" type="sphere" size="0.005" pos="0.035 0 0.0166" material="Light" />
										<geom name="light_2" type="sphere" size="0.005" pos="-0.035 0 0.0166" material="Light" />
										<geom name="kinova_robotiq_coupler_mesh" type="mesh" mesh="kinova_robotiq_coupler" pos="0 0 0.0466" material="GriMat" />
										<geom name="robotiq_85_base_link_mesh" type="mesh" mesh="robotiq_85_base_link" pos="0 0 0.0016" quat="0.707107 0 -0.707107 0" material="GriMat" />
										<body name="right_driver" pos="0 -0.0306011 0.054904" quat="0.707107 0 -0.707107 0">
											<geom name="right_driver_mesh" type="mesh" mesh="robotiq_85_knuckle_link" material="GriMat" contype="0" conaffinity="0" />
											<joint name="joint7_1" axis="0 0 1" type="hinge" limited="true" range="0 0.872664626" />
											<body name="right_coupler" pos="0 -0.0315 0">
												<geom name="right_coupler_mesh" type="mesh" mesh="robotiq_85_finger_link" material="GriMat" contype="0" conaffinity="0" />
												<joint name="joint8_1" axis="0 0 1" type="hinge" limited="true" range="0 2.967059728" />
												<body name="right_follower_link" pos="0.0475 -0.006 0">
													<geom name="right_follower_mesh" pos="0.0025 0.021 0" type="mesh" mesh="robotiq_85_finger_tip_link" material="GriMat" />
													<joint name="joint9_1" axis="0 0 1" type="hinge" limited="true" range="0 2.967059728" />
												</body>
											</body>
										</body>
										<body name="right_spring_link" pos="0.0016 -0.012 0.0614" quat="0.707107 0 -0.707107 0">
											<geom name="right_spring_mesh" type="mesh" pos="0 -0.0005 0.0016" mesh="robotiq_85_inner_knuckle_link" material="GriMat" contype="0" conaffinity="0" />
											<joint name="joint10_1" axis="0 0 1" type="hinge" limited="true" range="0 1" />
										</body>
										<body name="left_driver" pos="0 0.0306011 0.054904" quat="0 0.707107 0 0.707107">
											<geom name="left_driver_mesh" type="mesh" mesh="robotiq_85_knuckle_link" material="GriMat" contype="0" conaffinity="0" />
											<joint name="joint7_2" axis="0 0 1" type="hinge" limited="true" range="0 0.872664626" />
											<body name="left_coupler" pos="0 -0.0315 0">
												<geom name="left_coupler_mesh" type="mesh" mesh="robotiq_85_finger_link" material="GriMat" contype="0" conaffinity="0" />
												<joint name="joint8_2" axis="0 0 1" type="hinge" limited="true" range="0 2.967059728" />

												<body name="left_follower_link" pos="0.0475 -0.006 0">
													<geom name="left_follower_mesh" pos="0.0025 0.021 0" type="mesh" mesh="robotiq_85_finger_tip_link" material="GriMat" />
													<joint name="joint9_2" axis="0 0 1" type="hinge" limited="true" range="0 2.967059728" />
												</body>
											</body>
										</body>
										<body name="left_spring_link" pos="0.0016 0.012 0.0614" quat="0 0.707107 0 0.707107">
											<geom name="left_spring_mesh" type="mesh" pos="0 0.0005 0.0016" mesh="robotiq_85_inner_knuckle_link" material="GriMat" contype="0" conaffinity="0" />
											<joint name="joint10_2" axis="0 0 1" type="hinge" limited="true" range="0 1" />
										</body>
									</body>
								</body>
							</body>
						</body>
					</body>
				</body>
			</body>
		</body>
		<light directional="false" cutoff="90" exponent="1" diffuse="1 1 1" specular="0 0 0" pos="1 0 1.5" dir="-1 0 -2.5"/>
	</worldbody>
</mujoco>

