<mujoco model="JACO3_XML_V11">
	<compiler angle="radian"/>
	<size njmax="500" nconmax="100"/>
	<asset>
		<!-- Gen3 Arm Meshes -->
		<mesh name="Base_Link" file="gen3/Base_Link.stl"/>
		<mesh name="Shoulder_Link" file="gen3/Shoulder_Link.stl"/>
		<mesh name="HalfArm1_Link" file="gen3/HalfArm1_Link.stl"/>
		<mesh name="HalfArm2_Link" file="gen3/HalfArm2_Link.stl"/>
		<mesh name="ForeArm_Link" file="gen3/ForeArm_Link.stl"/>
		<mesh name="SphericalWrist1_Link" file="gen3/SphericalWrist1_Link.stl"/>
		<mesh name="SphericalWrist2_Link" file="gen3/SphericalWrist2_Link.stl"/>
		<mesh name="Bracelet_Link" file="gen3/Bracelet_Link.stl"/>
		<!-- Robotiq Hand Meshes -->
		<mesh name="robotiq_85_base_link_coarse" file="robotiq/robotiq_85_base_link_coarse.stl"/>
		<mesh name="outer_knuckle_coarse" file="robotiq/outer_knuckle_coarse.stl"/>
		<mesh name="outer_finger_coarse" file="robotiq/outer_finger_coarse.stl"/>
		<mesh name="inner_knuckle_coarse" file="robotiq/inner_knuckle_coarse.stl"/>
		<mesh name="inner_finger_coarse" file="robotiq/inner_finger_coarse.stl"/>
		<material name="BeigeMaterial" specular="0" shininess="0" reflectance="0" rgba="0.26 0.16 0.16796875 1" emission="0" />
	</asset>

    <actuator>
        <motor name="Shoulder_Link_motor" joint="Actuator1" gear="1 0 0 0 0 0" ctrlrange="0 0.8727" forcerange="-39 39"/>
        <motor name="HalfArm1_Link_motor" joint="Actuator2" gear="1 0 0 0 0 0" ctrlrange="0 0.8727" forcerange="-39 39"/>
        <motor name="HalfArm2_Link_motor" joint="Actuator3" gear="1 0 0 0 0 0" ctrlrange="0 0.8727" forcerange="-39 39"/>
        <motor name="ForeArm_Link_motor" joint="Actuator4" gear="1 0 0 0 0 0" ctrlrange="0 0.8727" forcerange="-39 39"/>
        <motor name="SphericalWrist1_Link_motor" joint="Actuator5" gear="1 0 0 0 0 0" ctrlrange="0 0.8727" forcerange="-9 9"/>
        <motor name="SphericalWrist2_Link_motor" joint="Actuator6" gear="1 0 0 0 0 0" ctrlrange="0 0.8727" forcerange="-9 9"/>
        <motor name="Bracelet_Link_motor" joint="Actuator7" gear="1 0 0 0 0 0" ctrlrange="0 0.8727" forcerange="-9 9"/>
    </actuator>

	<worldbody>
 		<geom name="floor" pos="0 0 -0.66" size="10 10 1" type="plane" rgba="1 0.83 0.61 1" material="BeigeMaterial" />
        <geom name="wall_1" pos="0 -2.5 1" size="2.5 2.5 1" type="plane" quat="0.707107 -0.707107 0 0" rgba="0.95 0.95 0.95 1" material="BeigeMaterial" />
        <geom name="wall_2" pos="-2.5 0 1" size="2.5 2.5 1" type="plane" quat="0.707107 0 0.707107 0" rgba="0.95 0.95 0.95 1" material="BeigeMaterial" />	
        	
        <body name="Base_Link" pos="0 0 0">
			<inertial pos="-0.000648 -0.000166 0.084487" mass="1.697353" fullinertia="0.004622 0.004495 0.002079 -9E-06 -6E-05 -9E-06"/>
			<geom type="mesh" rgba="0.79216 0.81961 0.93333 1" mesh="Base_Link"/>

		    <body name="Shoulder_Link" pos="6.1995e-05 0 0.15643" quat="-3.67321e-06 -1 0 0">
			<inertial pos="-2.3e-05 -0.010364 -0.07336" quat="0.707051 0.0451246 -0.0453544 0.704263" mass="1.37735" fullinertia="0.00457 0.004831 0.001409 -1E-06 -2E-06 -0.000448"/>
			<joint name="Actuator1" pos="0 0 0" axis="0 0 1"/>
			<geom type="mesh" rgba="0.75294 0.75294 0.75294 1" mesh="Shoulder_Link"/>

			<body name="HalfArm1_Link" pos="0 0.005375 -0.12838" quat="0.707105 0.707108 0 0">
				<inertial pos="-4.4e-05 -0.09958 -0.013278" quat="0.482348 0.516286 -0.516862 0.483366" mass="1.16367" diaginertia="0.0113017 0.011088 0.00102532"/>
				<joint name="Actuator2" pos="0 0 0" axis="0 0 1" limited="true" range="-2.2 2.2"/>
				<geom type="mesh" rgba="0.75294 0.75294 0.75294 1" mesh="HalfArm1_Link"/>

				<body name="HalfArm2_Link" pos="0 -0.21038 -0.006375" quat="0.707105 -0.707108 0 0">
					<inertial pos="-4.4e-05 -0.006641 -0.117892" quat="0.706144 0.0213722 -0.0209128 0.707437" mass="1.16366" diaginertia="0.0111633 0.010932 0.00100671"/>
					<joint name="Actuator3" pos="0 0 0" axis="0 0 1"/>
					<geom type="mesh" rgba="0.75294 0.75294 0.75294 1" mesh="HalfArm2_Link"/>

					<body name="ForeArm_Link" pos="0 0.006375 -0.21038" quat="0.707105 0.707108 0 0">
						<inertial pos="-1.8e-05 -0.075478 -0.015006" quat="0.483678 0.515961 -0.515859 0.483455" mass="0.930287" diaginertia="0.00834839 0.008147 0.000598606"/>
						<joint name="Actuator4" pos="0 0 0" axis="0 0 1" limited="true" range="-2.5656 2.5656"/>
						<geom type="mesh" rgba="0.75294 0.75294 0.75294 1" mesh="ForeArm_Link"/>

						<body name="SphericalWrist1_Link" pos="0 -0.20843 -0.006375" quat="0.707105 -0.707108 0 0">
							<inertial pos="1e-06 -0.009432 -0.063883" quat="0.703558 0.0707492 -0.0707492 0.703558" mass="0.678106" diaginertia="0.00165901 0.001596 0.000346988"/>
							<joint name="Actuator5" pos="0 0 0" axis="0 0 1"/>
							<geom type="mesh" rgba="0.75294 0.75294 0.75294 1" mesh="SphericalWrist1_Link"/>

							<body name="SphericalWrist2_Link" pos="0 0.00017505 -0.10593" quat="0.707105 0.707108 0 0">
								<inertial pos="1e-06 -0.045483 -0.00965" quat="0.44426 0.550121 -0.550121 0.44426" mass="0.678106" diaginertia="0.00170087 0.001641 0.00035013"/>
								<joint name="Actuator6" pos="0 0 0" axis="0 0 1" limited="true" range="-2.05 2.05"/>
								<geom type="mesh" rgba="0.75294 0.75294 0.75294 1" mesh="SphericalWrist2_Link"/>

								<body name="Bracelet_Link" pos="0 -0.10593 -0.00017505" quat="0.707105 -0.707108 0 0">
									<inertial pos="-0.000281 -0.011402 -0.03108" quat="0.592556 0.413116 -0.393675 0.568536" mass="0.500657" diaginertia="0.000650457 0.00056985 0.000310694"/>
									<joint name="Actuator7" pos="0 0 0" axis="0 0 1"/>
									<geom type="mesh" rgba="0.75294 0.75294 0.75294 1" mesh="Bracelet_Link"/>

									<!-- Robotiq Gripper Links -->
									<body name="ee_link" pos="0 0 -0.064" quat="0.707105 -0.707108 0 0">
										<inertial pos="-0.01 0 0" mass="0.001"  diaginertia="1.66667e-08 1.66667e-08 1.66667e-08" />
										<geom size="0.005 0.005 0.005" friction="0.8 0.8 0.8" pos="-0.01 0 0" type="box" />

										<body name="robotiq_85_base_link" pos="0 0 0" quat="0.707105 -0.707108 0 0">
											<inertial pos="0.00021987 -2.3546e-10 0.030163"  quat="0.707058 0.00723369 0.00723345 0.707081" mass="0.30915" diaginertia="0.00030737 0.000289758 0.000199102" />
											<geom type="mesh" rgba="0.1 0.1 0.1 1" friction="0.8 0.8 0.8" mesh="robotiq_85_base_link_coarse" />

											<body name="left_outer_knuckle" pos="0.0306011 0 0.062792">
												<inertial pos="0.0178332 3.68915e-11 0.00214425"  quat="0.463241 0.534235 0.534235 0.463241" mass="0.00684839" diaginertia="1.38892e-06 1.28691e-06 2.45951e-07" />
												<geom type="mesh" rgba="0.1 0.1 0.1 1" friction="0.2 0. 0.4" mesh="outer_knuckle_coarse" />
												<body name="left_outer_finger" pos="0.031691 0 -0.00193396">
													<inertial pos="0.00131452 0 0.0215404"  quat="0.999536 0 -0.0304703 0" mass="0.0273094" diaginertia="8.53972e-06 6.91333e-06 2.22664e-06" />
													<geom type="mesh" rgba="0.1 0.1 0.1 1" friction="0.8 0.8 0.8" mesh="outer_finger_coarse" />
												</body>
											</body>

											<body name="left_inner_knuckle" pos="0.0127 0 0.0693075">
												<inertial pos="0.0170975 -3.93809e-10 0.0224918"   quat="0.947655 0 -0.319297 0" mass="0.0110931" diaginertia="5.59353e-06 3.96549e-06 1.88108e-06" />
												<geom type="mesh" rgba="0.1 0.1 0.1 1" friction="0.8 0.8 0.8" mesh="inner_knuckle_coarse" />

												<body name="left_inner_finger" pos="0.0345853 0 0.045497" >
													<inertial pos="0.00602756 0 0.00669926"  quat="0.699065 0.106339 0.106339 0.699065" mass="0.00724255" diaginertia="1.70064e-06 1.58577e-06 3.69621e-07" />
													<geom type="mesh" rgba="0.1 0.1 0.1 1" friction="0.8 0.8 0.8" mesh="inner_finger_coarse" />
													<joint axis="1 0 0" name="left_inner_finger_joint" range="0 0.05" type="slide"></joint>
												</body>
											</body>

											<body name="right_inner_knuckle" pos="-0.0127 0 0.0693075" quat="0 0 0 1">
												<inertial pos="0.0168606 3.93808e-10 0.02267"  quat="0.949317 0 -0.314322 0" mass="0.0110931" diaginertia="5.59353e-06 3.96549e-06 1.88108e-06" />
												<geom type="mesh" rgba="0.1 0.1 0.1 1" friction="0.8 0.8 0.8" mesh="inner_knuckle_coarse" />
												<body name="right_inner_finger" pos="0.034106 0 0.0458574">
													<inertial pos="0.00602756 0 0.00669926"  quat="0.699065 0.106339 0.106339 0.699065" mass="0.00724255" diaginertia="1.70064e-06 1.58577e-06 3.69621e-07" />
													<geom type="mesh" rgba="0.1 0.1 0.1 1" friction="0.8 0.8 0.8" mesh="inner_finger_coarse" />
													<joint axis="-1 0 0" name="right_inner_finger_joint" range="0 0.05" type="slide"></joint>
												</body>
											</body>

											<body name="right_outer_knuckle" pos="-0.0306011 0 0.062792" quat="0 0 0 1">
												<inertial pos="0.0178097 3.60493e-11 0.00233123"  quat="0.460432 0.536658 0.536658 0.460432" mass="0.00684839" diaginertia="1.38892e-06 1.28691e-06 2.45951e-07" />
												<geom type="mesh" rgba="0.1 0.1 0.1 1" friction="0.8 0.8 0.8" mesh="outer_knuckle_coarse" />
												<body name="right_outer_finger" pos="0.0317096 0 -0.00160136">
													<inertial pos="0.00108844 0 0.021553"  quat="0.999682 0 -0.0252262 0" mass="0.0273094" diaginertia="8.53972e-06 6.91333e-06 2.22664e-06" />
													<geom type="mesh" rgba="0.1 0.1 0.1 1" friction="0.8 0.8 0.8" mesh="outer_finger_coarse" />
												</body>
											</body>
										</body>
									</body>
								</body>
							</body>
						</body>
					</body>
				</body>
			</body>
		</body>
        </body>
		<light directional="false" cutoff="90" exponent="1" diffuse="1 1 1" specular="0 0 0" pos="1 0 1.5" dir="-1 0 -2.5"/>
	</worldbody>
</mujoco>

